Workbook

Sheet RELATORIO CONTROLADORIA
B1: COLABORADOR : | C1: Equipe | D1: RET. COM DESCONTO | E1: IND. 4% DO TOTAL | F1: RET. | G1: RETIRADA | H1: INSTALAÇÃO | I1: MANUTENÇÃO | J1: AT. | K1: P.V | L1: D.A. | M1: ATESTADO | N1: D.U | O1: D.C. | P1: MED. | Q1: valor | R1: Resultado
A2: Ind. Retrabalho | B2: COLABORADOR : | D2: 74.2 | E2: 219.8 | F2: 244 | G2: 49 | H2: 1206 | I2: 4006 | J2: 5495 | K2: 5420.8 | L2: 0 | M2: 0 | N2: 1262 | O2: 1460 | P2: 3.7 | Q2: 18499
A3: 0.0417 | B3: ALEFF PEREIRA SOARES | C3: INSTALAÇÃO | D3: 0.2 | E3: 4.8 | F3: 5 | H3: 42 | I3: 72 | J3: 120 | K3: 119.8 | N3: 24 | O3: 24 | P3: 4.99 | Q3: 594 | R3: Concessão
A4: 0.0303 | B4: ALLYSSON DA SILVA MARINHO | C4: MISTO | D4: 0 | E4: 3.96 | F4: 3 | H4: 20 | I4: 75 | J4: 99 | K4: 99 | N4: 24 | O4: 22 | P4: 4.5 | Q4: 0 | R4: -
A5: 0.0429 | B5: ANDRE SILVA LOIOLA | C5: MISTO | D5: 0.2 | E5: 2.8 | F5: 3 | H5: 3 | I5: 63 | J5: 70 | K5: 69.8 | N5: 24 | O5: 25 | P5: 2.79 | Q5: 0 | R5: -
A6: 0 | B6: ANTONIO CARLOS BARBOSA DE SOUSA | C6: JEBnet | D6: 0 | E6: 0.08 | H6: 2 | J6: 2 | K6: 2 | O6: 21 | P6: 0.1 | Q6: - | R6: -
A7: 0.0734 | B7: ANTONIO CARLOS FERREIRA DA SILVA | C7: INSTALAÇÃO | D7: 3.6 | E7: 4.36 | F7: 8 | G7: 2 | H7: 33 | I7: 69 | J7: 109 | K7: 105.4 | N7: 23 | O7: 23 | P7: 4.58 | Q7: 353.44 | R7: Premio
A8: 0.0761 | B8: ANTONIO EDUARDO TEIXEIRA CAMELO | C8: MISTO | D8: 3.3 | E8: 3.68 | F8: 7 | H8: 18 | I8: 70 | J8: 92 | K8: 88.7 | N8: 23 | O8: 22 | P8: 4.03 | Q8: 0 | R8: -
A9: 0 | B9: ANTONIO EUNARDES SOUSA BRAGA | C9: JEBnet | D9: 0 | E9: 2.76 | H9: 1 | I9: 68 | J9: 69 | K9: 69 | O9: 23 | P9: 3 | Q9: - | R9: -
A10: 0.03 | B10: ANTONIO FELIPE CASTRO DE OLIVEIRA | C10: MISTO COND. | D10: 0 | E10: 4 | F10: 3 | G10: 5 | H10: 25 | I10: 67 | J10: 100 | K10: 100 | N10: 23 | O10: 23 | P10: 4.35 | Q10: 678 | R10: Premio
A11: 0.092 | B11: ANTONIO RAFAEL ALEXANDRE DE SOUSA | C11: MISTO | D11: 4.5 | E11: 3.48 | F11: 8 | H11: 17 | I11: 66 | J11: 87 | K11: 82.5 | N11: 23 | O11: 21 | P11: 3.93 | Q11: 0 | R11: Premio não atingido
A12: 0 | B12: ANTONIO TIAGO AMANCIO DA SILVA | C12: INSTALAÇÃO | D12: 0 | E12: 0.68 | G12: 4 | H12: 1 | I12: 12 | J12: 17 | K12: 17 | O12: 24 | P12: 0.71 | Q12: 51 | R12: Premio
A13: 0.0088 | B13: ANTONIO WILSON SOARES DE SOUSA | C13: JEBnet | D13: 0 | E13: 4.52 | F13: 1 | H13: 44 | I13: 68 | J13: 113 | K13: 113 | O13: 24 | P13: 4.71 | Q13: - | R13: -
A14: 0.0588 | B14: ARLISON DA SILVA PEREIRA | C14: MISTO | D14: 1.6 | E14: 3.4 | F14: 5 | H14: 8 | I14: 71 | J14: 85 | K14: 83.4 | N14: 24 | O14: 23 | P14: 3.63 | Q14: 0 | R14: Premio não atingido
A15: 0.0606 | B15: BRENDHOWN CESAR VIANA SILVA FALCAO | C15: MISTO COND. | D15: 2 | E15: 3.96 | F15: 6 | G15: 2 | H15: 18 | I15: 75 | J15: 99 | K15: 97 | N15: 24 | O15: 23 | P15: 4.22 | Q15: 665.84 | R15: Premio
A16: 0.0843 | B16: BRUNO MATIAS DA SILVA | C16: MISTO COND. | D16: 3.7 | E16: 3.32 | F16: 7 | H16: 22 | I16: 57 | J16: 83 | K16: 79.3 | N16: 24 | O16: 22 | P16: 3.61 | Q16: 609.28 | R16: Premio
A17: 0.2222 | B17: BRUNO MOREIRA MONTEIRO | C17: MISTO | D17: 3.3 | E17: 0.72 | F17: 4 | H17: 8 | I17: 9 | J17: 18 | K17: 14.7 | N17: 23 | O17: 25 | P17: 0.59 | Q17: 0 | R17: Premio não atingido
A18: 0.0923 | B18: CAIO VICTOR MONTEIRO DE OLIVEIRA | C18: MISTO | D18: 3.4 | E18: 2.6 | F18: 6 | H18: 11 | I18: 46 | J18: 65 | K18: 61.6 | N18: 23 | O18: 18 | P18: 3.42 | Q18: 0 | R18: Premio não atingido
A19: 0.0971 | B19: CARLOS HENRIQUE LINO SILVA | C19: MISTO COND. | D19: 5.9 | E19: 4.12 | F19: 10 | H19: 27 | I19: 67 | J19: 103 | K19: 97.1 | N19: 24 | O19: 22 | P19: 4.41 | Q19: 680.48 | R19: Premio
A20: 0.075 | B20: CLAUDIANO CICINATO DA SILVA | C20: INSTALAÇÃO | D20: 2.8 | E20: 3.2 | F20: 6 | G20: 3 | H20: 27 | I20: 46 | J20: 80 | K20: 77.2 | N20: 24 | O20: 22 | P20: 3.51 | Q20: 231.6 | R20: Premio
A21: 0.0133 | B21: DANILO OLIVEIRA DE SOUSA | C21: MISTO | D21: 0 | E21: 3 | F21: 1 | H21: 6 | I21: 64 | J21: 75 | K21: 75 | O21: 24 | P21: 3.13 | Q21: 0 | R21: Premio não atingido
A22: 0.0784 | B22: DAVI MEDINA DE ARAUJO | C22: INSTALAÇÃO | D22: 3.9 | E22: 4.08 | F22: 8 | H22: 34 | I22: 66 | J22: 102 | K22: 98.1 | N22: 23 | O22: 23 | P22: 4.26 | Q22: 324.32 | R22: Premio
A23: 0.08 | B23: DIEGO DA SILVA ASSUNCAO | C23: MISTO | D23: 2 | E23: 2 | F23: 4 | H23: 7 | I23: 41 | J23: 50 | K23: 48 | O23: 23 | P23: 2.09 | Q23: 0 | R23: Premio não atingido
A24: 0.0313 | B24: EDUARDO SANTOS DA SILVA | C24: GIGA | D24: 0 | E24: 1.28 | F24: 1 | H24: 5 | I24: 27 | J24: 32 | K24: 32 | O24: 23 | P24: 1.39 | Q24: 270.3 | R24: Premio
A25: 0.0381 | B25: ELISSON PEREIRA COUTINHO NOVAIS | C25: MISTO | D25: 0 | E25: 4.2 | F25: 4 | H25: 14 | I25: 87 | J25: 105 | K25: 105 | N25: 23 | O25: 22 | P25: 4.77 | Q25: 285 | R25: Concessão
A26: 0.0538 | B26: ELIZEU DA SILVA FERREIRA | C26: INSTALAÇÃO | D26: 1.3 | E26: 3.72 | F26: 5 | H26: 15 | I26: 74 | J26: 93 | K26: 91.7 | N26: 23 | O26: 22 | P26: 4.17 | Q26: 314.88 | R26: Premio
A27: 0.0571 | B27: EVERLAN DA PENHA TOME | C27: MISTO | D27: 1.2 | E27: 2.8 | F27: 4 | H27: 7 | I27: 60 | J27: 70 | K27: 68.8 | N27: 23 | O27: 21 | P27: 3.28 | Q27: 0 | R27: Premio não atingido
A28: 0.0167 | B28: FELIPE MARTINS DAMASCENO | C28: INSTALAÇÃO | D28: 0 | E28: 2.4 | F28: 1 | H28: 16 | I28: 43 | J28: 60 | K28: 60 | N28: 23 | O28: 23 | P28: 2.61 | Q28: 180 | R28: Premio
A29: 0.0455 | B29: FRANCISCO CARLOS EUGENIO DO NASCIMENTO | C29: MISTO | D29: 0.2 | E29: 1.76 | F29: 2 | H29: 7 | I29: 36 | J29: 44 | K29: 43.8 | N29: 16 | O29: 11 | P29: 3.98 | Q29: 0 | R29: -
A30: 0.0211 | B30: FRANCISCO DAS CHAGAS E SILVA ROCHA | C30: INSTALAÇÃO | D30: 0 | E30: 3.8 | F30: 2 | G30: 2 | H30: 13 | I30: 77 | J30: 95 | K30: 95 | N30: 24 | O30: 23 | P30: 4.13 | Q30: 312 | R30: Premio
A31: 0.0756 | B31: FRANCISCO DIEGO ALVES FERREIRA | C31: INSTALAÇÃO | D31: 4.2 | E31: 4.76 | F31: 9 | H31: 52 | I31: 58 | J31: 119 | K31: 114.8 | N31: 24 | O31: 22 | P31: 5.22 | Q31: 628.56 | R31: Premio
A32: 0.0323 | B32: FRANCISCO FELIPE DE LIMA ALVES | C32: MISTO | D32: 0 | E32: 1.24 | F32: 1 | H32: 4 | I32: 27 | J32: 31 | K32: 31 | N32: 6 | O32: 6 | P32: 5.17 | Q32: - | R32: Premio
A33: 0.0361 | B33: FRANCISCO HELIO MARINHO CUNHA NETO | C33: INSTALAÇÃO | D33: 0 | E33: 3.32 | F33: 3 | G33: 3 | H33: 21 | I33: 57 | J33: 83 | K33: 83 | N33: 23 | O33: 16 | P33: 5.19 | Q33: 618 | R33: Premio
A34: 0.1013 | B34: FRANCISCO JHONATA DA COSTA | C34: MISTO | D34: 4.8 | E34: 3.16 | F34: 8 | H34: 9 | I34: 64 | J34: 79 | K34: 74.2 | N34: 24 | O34: 18 | P34: 4.12 | Q34: 0 | R34: Premio não atingido
A35: 0.1045 | B35: FRANCISCO LAERTE PEREIRA RODRIGUES | C35: MISTO COND. | D35: 4.3 | E35: 2.68 | F35: 7 | G35: 1 | H35: 21 | I35: 39 | J35: 67 | K35: 62.7 | N35: 23 | O35: 21 | P35: 2.98 | Q35: 0 | R35: Premio não atingido
A36: 0.0641 | B36: FRANCISCO MATHEUS PEREIRA MENDES | C36: INSTALAÇÃO | D36: 1.9 | E36: 3.12 | F36: 5 | H36: 18 | I36: 53 | J36: 78 | K36: 76.1 | N36: 23 | O36: 22 | P36: 3.46 | Q36: 228.36 | R36: Premio
A37: 0.043 | B37: FRANCISCO TIAGO PINHEIRO | C37: MISTO | D37: 0.3 | E37: 3.72 | F37: 4 | H37: 10 | I37: 80 | J37: 93 | K37: 92.7 | N37: 23 | O37: 20 | P37: 4.64 | Q37: 0 | R37: Premio não atingido
A38: 0.0179 | B38: GABRIEL MARTINS MUNIZ | C38: INSTALAÇÃO | D38: 0 | E38: 6.72 | F38: 3 | G38: 4 | H38: 99 | I38: 62 | J38: 168 | K38: 168 | N38: 24 | O38: 24 | P38: 7 | Q38: 1200 | R38: -
A39: 0.0081 | B39: GEILSON DA SILVA MOURA | C39: MISTO COND. | D39: 0 | E39: 4.92 | F39: 1 | G39: 2 | H39: 42 | I39: 76 | J39: 123 | K39: 123 | N39: 23 | O39: 24 | P39: 5.13 | Q39: 990 | R39: Premio
A40: 0.0157 | B40: GILVAN ASSUNCAO SILVA | C40: MISTO | D40: 0 | E40: 5.08 | F40: 2 | H40: 10 | I40: 115 | J40: 127 | K40: 127 | N40: 21 | O40: 17 | P40: 7.47 | Q40: 964 | R40: -
...

Sheet FDT
A1: WA.ME/55 | B1: 959 | D1: 68 | E1: WA.ME/55 | F1: 959
A2: CONTATO WPP | B2: WHATSAPP | D2: TECNICO | E2: CONTATO WPP | F2: WHATSAPP | H2: CPF
C3: #N/A | G3: =C3 -> #N/A | H3: =IFERROR(VLOOKUP(D3,CPF!A:D,4,0),"NAO ENCONTRADO") -> NAO ENCONTRADO
B4: =CONCATENATE($A$1,A4) -> WA.ME/55 | C4: ALAN SOUTO | D4: ALAN FEITOSA DE SOUTO | F4: =CONCATENATE($E$1,E4) -> WA.ME/55 | G4: =C4 -> ALAN SOUTO | H4: =IFERROR(VLOOKUP(D4,CPF!A:D,4,0),"NAO ENCONTRADO") -> 646.525.643-68
B5: =CONCATENATE($A$1,A5) -> WA.ME/55 | C5: ALAN SOUTO | D5: ANTONIO TIAGO AMANCIO DA SILVA | F5: =CONCATENATE($E$1,E5) -> WA.ME/55 | G5: =C5 -> ALAN SOUTO | H5: =IFERROR(VLOOKUP(D5,CPF!A:D,4,0),"NAO ENCONTRADO") -> NAO ENCONTRADO
B6: =CONCATENATE($A$1,A6) -> WA.ME/55 | C6: ALAN SOUTO | D6: FRANCISCO LAERTE PEREIRA RODRIGUES | F6: =CONCATENATE($E$1,E6) -> WA.ME/55 | G6: =C6 -> ALAN SOUTO | H6: =IFERROR(VLOOKUP(D6,CPF!A:D,4,0),"NAO ENCONTRADO") -> NAO ENCONTRADO
B7: =CONCATENATE($A$1,A7) -> WA.ME/55 | C7: ALAN SOUTO | D7: JOAO PAULO DA SILVA LIMA | F7: =CONCATENATE($E$1,E7) -> WA.ME/55 | G7: =C7 -> ALAN SOUTO | H7: =IFERROR(VLOOKUP(D7,CPF!A:D,4,0),"NAO ENCONTRADO") -> 001.058.623-71
B8: =CONCATENATE($A$1,A8) -> WA.ME/55 | C8: ALAN SOUTO | D8: JOSE MARIA DA COSTA LEONARDO | F8: =CONCATENATE($E$1,E8) -> WA.ME/55 | G8: =C8 -> ALAN SOUTO | H8: =IFERROR(VLOOKUP(D8,CPF!A:D,4,0),"NAO ENCONTRADO") -> 734.146.113-68
B9: =CONCATENATE($A$1,A9) -> WA.ME/55 | C9: ALAN SOUTO | D9: KELTON CLEMENTE DOS SANTOS | F9: =CONCATENATE($E$1,E9) -> WA.ME/55 | G9: =C9 -> ALAN SOUTO | H9: =IFERROR(VLOOKUP(D9,CPF!A:D,4,0),"NAO ENCONTRADO") -> 013.487.253-38
B10: =CONCATENATE($A$1,A10) -> WA.ME/55 | C10: MARCOS VICTOR | D10: LUIZ OCTAVIO ALMEIDA DA SILVA | F10: =CONCATENATE($E$1,E10) -> WA.ME/55 | G10: =C10 -> MARCOS VICTOR | H10: =IFERROR(VLOOKUP(D10,CPF!A:D,4,0),"NAO ENCONTRADO") -> 087.399.743-32
B11: =CONCATENATE($A$1,A11) -> WA.ME/55 | C11: ALAN SOUTO | D11: MAILSON FRANCISCO PEREIRA | F11: =CONCATENATE($E$1,E11) -> WA.ME/55 | G11: =C11 -> ALAN SOUTO | H11: =IFERROR(VLOOKUP(D11,CPF!A:D,4,0),"NAO ENCONTRADO") -> 062.780.033-50
B12: =CONCATENATE($A$1,A12) -> WA.ME/55 | C12: ALAN SOUTO | D12: MARCOS VICTOR LOPES MEDEIROS FONSECA | F12: =CONCATENATE($E$1,E12) -> WA.ME/55 | G12: =C12 -> ALAN SOUTO | H12: =IFERROR(VLOOKUP(D12,CPF!A:D,4,0),"NAO ENCONTRADO") -> 034.029.363-21
B13: =CONCATENATE($A$1,A13) -> WA.ME/55 | C13: ALAN SOUTO | D13: WILLIAM ADRIANO DANTAS | F13: =CONCATENATE($E$1,E13) -> WA.ME/55 | G13: =C13 -> ALAN SOUTO | H13: =IFERROR(VLOOKUP(D13,CPF!A:D,4,0),"NAO ENCONTRADO") -> 070.038.853-28
B14: =CONCATENATE($A$1,A14) -> WA.ME/55 | C14: ALAN SOUTO | F14: =CONCATENATE($E$1,E14) -> WA.ME/55 | G14: =C14 -> ALAN SOUTO | H14: =IFERROR(VLOOKUP(D14,CPF!A:D,4,0),"NAO ENCONTRADO") -> NAO ENCONTRADO
B15: =CONCATENATE($A$1,A15) -> WA.ME/55 | C15: ALAN SOUTO | F15: =CONCATENATE($E$1,E15) -> WA.ME/55 | G15: =C15 -> ALAN SOUTO | H15: =IFERROR(VLOOKUP(D15,CPF!A:D,4,0),"NAO ENCONTRADO") -> NAO ENCONTRADO
B16: =CONCATENATE($A$1,A16) -> WA.ME/55 | C16: ALAN SOUTO | F16: =CONCATENATE($E$1,E16) -> WA.ME/55 | G16: =C16 -> ALAN SOUTO | H16: =IFERROR(VLOOKUP(D16,CPF!A:D,4,0),"NAO ENCONTRADO") -> NAO ENCONTRADO
B17: =CONCATENATE($A$1,A17) -> WA.ME/55 | C17: ALAN SOUTO | F17: =CONCATENATE($E$1,E17) -> WA.ME/55 | G17: =C17 -> ALAN SOUTO | H17: =IFERROR(VLOOKUP(D17,CPF!A:D,4,0),"NAO ENCONTRADO") -> NAO ENCONTRADO
B18: =CONCATENATE($A$1,A18) -> WA.ME/55 | C18: ALAN SOUTO | F18: =CONCATENATE($E$1,E18) -> WA.ME/55 | G18: =C18 -> ALAN SOUTO | H18: =IFERROR(VLOOKUP(D18,CPF!A:D,4,0),"NAO ENCONTRADO") -> NAO ENCONTRADO
B19: =CONCATENATE($A$1,A19) -> WA.ME/55 | C19: JEBNET | D19: ANTONIO CARLOS BARBOSA SOUSA | F19: =CONCATENATE($E$1,E19) -> WA.ME/55 | G19: =C19 -> JEBNET | H19: =IFERROR(VLOOKUP(D19,CPF!A:D,4,0),"NAO ENCONTRADO") -> NAO ENCONTRADO
B20: =CONCATENATE($A$1,A20) -> WA.ME/55 | C20: JEBNET | D20: ANTONIO EUNARDES SOUSA BRAGA | F20: =CONCATENATE($E$1,E20) -> WA.ME/55 | G20: =C20 -> JEBNET | H20: =IFERROR(VLOOKUP(D20,CPF!A:D,4,0),"NAO ENCONTRADO") -> NAO ENCONTRADO
B21: =CONCATENATE($A$1,A21) -> WA.ME/55 | C21: JEBNET | D21: ANTONIO WILSON SOARES DE SOUSA | F21: =CONCATENATE($E$1,E21) -> WA.ME/55 | G21: =C21 -> JEBNET | H21: =IFERROR(VLOOKUP(D21,CPF!A:D,4,0),"NAO ENCONTRADO") -> NAO ENCONTRADO
B22: =CONCATENATE($A$1,A22) -> WA.ME/55 | C22: JEBNET | D22: EMANUEL ALBANO GOMES | F22: =CONCATENATE($E$1,E22) -> WA.ME/55 | G22: =C22 -> JEBNET | H22: =IFERROR(VLOOKUP(D22,CPF!A:D,4,0),"NAO ENCONTRADO") -> NAO ENCONTRADO
B23: =CONCATENATE($A$1,A23) -> WA.ME/55 | C23: JEBNET | D23: FRANCISCO DA SILVA RODRIGUES | F23: =CONCATENATE($E$1,E23) -> WA.ME/55 | G23: =C23 -> JEBNET | H23: =IFERROR(VLOOKUP(D23,CPF!A:D,4,0),"NAO ENCONTRADO") -> NAO ENCONTRADO
B24: =CONCATENATE($A$1,A24) -> WA.ME/55 | C24: JEBNET | D24: FRANCISCO JOSE FREITAS NEO | F24: =CONCATENATE($E$1,E24) -> WA.ME/55 | G24: =C24 -> JEBNET | H24: =IFERROR(VLOOKUP(D24,CPF!A:D,4,0),"NAO ENCONTRADO") -> NAO ENCONTRADO
B25: =CONCATENATE($A$1,A25) -> WA.ME/55 | C25: JEBNET | D25: FRANCISCO RAFAEL DIAS | F25: =CONCATENATE($E$1,E25) -> WA.ME/55 | G25: =C25 -> JEBNET | H25: =IFERROR(VLOOKUP(D25,CPF!A:D,4,0),"NAO ENCONTRADO") -> NAO ENCONTRADO
B26: =CONCATENATE($A$1,A26) -> WA.ME/55 | C26: JEBNET | D26: FRANCISCO YURI DA COSTA MARTINS | F26: =CONCATENATE($E$1,E26) -> WA.ME/55 | G26: =C26 -> JEBNET | H26: =IFERROR(VLOOKUP(D26,CPF!A:D,4,0),"NAO ENCONTRADO") -> NAO ENCONTRADO
B27: =CONCATENATE($A$1,A27) -> WA.ME/55 | C27: JEBNET | D27: JOAO ADAILSON GOMES ALBANO | F27: =CONCATENATE($E$1,E27) -> WA.ME/55 | G27: =C27 -> JEBNET | H27: =IFERROR(VLOOKUP(D27,CPF!A:D,4,0),"NAO ENCONTRADO") -> NAO ENCONTRADO
B28: =CONCATENATE($A$1,A28) -> WA.ME/55 | C28: JEBNET | D28: JOAO BATISTA COELHO GOMES | F28: =CONCATENATE($E$1,E28) -> WA.ME/55 | G28: =C28 -> JEBNET | H28: =IFERROR(VLOOKUP(D28,CPF!A:D,4,0),"NAO ENCONTRADO") -> NAO ENCONTRADO
B29: =CONCATENATE($A$1,A29) -> WA.ME/55 | C29: JEBNET | D29: MICHEL PLATINI CORREIA MORAIS | F29: =CONCATENATE($E$1,E29) -> WA.ME/55 | G29: =C29 -> JEBNET | H29: =IFERROR(VLOOKUP(D29,CPF!A:D,4,0),"NAO ENCONTRADO") -> NAO ENCONTRADO
B30: =CONCATENATE($A$1,A30) -> WA.ME/55 | C30: JEBNET | D30: MILTON FERREIRA DE CASTRO | F30: =CONCATENATE($E$1,E30) -> WA.ME/55 | G30: =C30 -> JEBNET | H30: =IFERROR(VLOOKUP(D30,CPF!A:D,4,0),"NAO ENCONTRADO") -> NAO ENCONTRADO
... B69: =CONCATENATE($A$1,A69) -> WA.ME/55 | C69: MAILSON FRANCISCO | D69: YVINA CHAGAS ALENCAR | F69: =CONCATENATE($E$1,E69) -> WA.ME/55 | G69: =C69 -> MAILSON FRANCISCO | H69: =IFERROR(VLOOKUP(D69,CPF!A:D,4,0),"NAO ENCONTRADO") -> 080.135.683-00
B70: =CONCATENATE($A$1,A70) -> WA.ME/55 | C70: MAILSON FRANCISCO | F70: =CONCATENATE($E$1,E70) -> WA.ME/55 | G70: =C70 -> MAILSON FRANCISCO | H70: =IFERROR(VLOOKUP(D70,CPF!A:D,4,0),"NAO ENCONTRADO") -> NAO ENCONTRADO
B71: =CONCATENATE($A$1,A71) -> WA.ME/55 | C71: MAILSON FRANCISCO | F71: =CONCATENATE($E$1,E71) -> WA.ME/55 | G71: =C71 -> MAILSON FRANCISCO | H71: =IFERROR(VLOOKUP(D71,CPF!A:D,4,0),"NAO ENCONTRADO") -> NAO ENCONTRADO
B72: =CONCATENATE($A$1,A72) -> WA.ME/55 | C72: MAILSON FRANCISCO | F72: =CONCATENATE($E$1,E72) -> WA.ME/55 | G72: =C72 -> MAILSON FRANCISCO | H72: =IFERROR(VLOOKUP(D72,CPF!A:D,4,0),"NAO ENCONTRADO") -> NAO ENCONTRADO
B73: =CONCATENATE($A$1,A73) -> WA.ME/55 | C73: MAILSON FRANCISCO | F73: =CONCATENATE($E$1,E73) -> WA.ME/55 | G73: =C73 -> MAILSON FRANCISCO | H73: =IFERROR(VLOOKUP(D73,CPF!A:D,4,0),"NAO ENCONTRADO") -> NAO ENCONTRADO
B74: =CONCATENATE($A$1,A74) -> WA.ME/55 | C74: MAILSON FRANCISCO | F74: =CONCATENATE($E$1,E74) -> WA.ME/55 | G74: =C74 -> MAILSON FRANCISCO | H74: =IFERROR(VLOOKUP(D74,CPF!A:D,4,0),"NAO ENCONTRADO") -> NAO ENCONTRADO
B75: =CONCATENATE($A$1,A75) -> WA.ME/55 | C75: MAILSON FRANCISCO | F75: =CONCATENATE($E$1,E75) -> WA.ME/55 | G75: =C75 -> MAILSON FRANCISCO | H75: =IFERROR(VLOOKUP(D75,CPF!A:D,4,0),"NAO ENCONTRADO") -> NAO ENCONTRADO
B76: =CONCATENATE($A$1,A76) -> WA.ME/55 | C76: MARCOS VICTOR | D76: ANDRE SILVA LOIOLA | F76: =CONCATENATE($E$1,E76) -> WA.ME/55 | G76: =C76 -> MARCOS VICTOR | H76: =IFERROR(VLOOKUP(D76,CPF!A:D,4,0),"NAO ENCONTRADO") -> 066.675.003-38
B77: =CONCATENATE($A$1,A77) -> WA.ME/55 | C77: MARCOS VICTOR | D77: ANTONIO FELIPE CASTRO DE OLIVEIRA | F77: =CONCATENATE($E$1,E77) -> WA.ME/55 | G77: =C77 -> MARCOS VICTOR | H77: =IFERROR(VLOOKUP(D77,CPF!A:D,4,0),"NAO ENCONTRADO") -> 071.005.963-94
B78: =CONCATENATE($A$1,A78) -> WA.ME/55 | C78: MARCOS VICTOR | D78: ANTONIO FELIPE SOARES SILVA TAVARES | F78: =CONCATENATE($E$1,E78) -> WA.ME/55 | G78: =C78 -> MARCOS VICTOR | H78: =IFERROR(VLOOKUP(D78,CPF!A:D,4,0),"NAO ENCONTRADO") -> 076.287.933-55
...

Sheet TABELA DE METAS
F1: DIAS TRABALHADOS
B2: Premiação | C2: VALOR | D2: META/DIA | E2: AE | F2: 31 | G2: 30 | H2: 29 | I2: 28 | J2: 27 | K2: 26 | L2: 25 | M2: 24 | N2: 23 | O2: 22 | P2: 21 | Q2: 20 | R2: 19 | S2: 18 | T2: 17 | U2: 16 | V2: 15 | W2: 14 | X2: 13 | Y2: 12 | Z2: 11
A3: MISTO | B3: PRATA | C3: 300 | D3: 5 | E3: 4 | F3: 155 | G3: 150 | H3: 145 | I3: 140 | J3: 135 | K3: 130 | L3: 125 | M3: 120 | N3: 115 | O3: 110 | P3: 105 | Q3: 100 | R3: 95 | S3: 90 | T3: 85 | U3: 80 | V3: 75 | W3: 70 | X3: 65 | Y3: 60 | Z3: 55
A4: MISTO | B4: OURO | C4: 600 | D4: 6 | E4: 6 | F4: 186 | G4: 180 | H4: 174 | I4: 168 | J4: 162 | K4: 156 | L4: 150 | M4: 144 | N4: 138 | O4: 132 | P4: 126 | Q4: 120 | R4: 114 | S4: 108 | T4: 102 | U4: 96 | V4: 90 | W4: 84 | X4: 78 | Y4: 72 | Z4: 66
A5: MISTO | B5: PLATINA | C5: 900 | D5: 7 | E5: 8 | F5: 217 | G5: 210 | H5: 203 | I5: 196 | J5: 189 | K5: 182 | L5: 175 | M5: 168 | N5: 161 | O5: 154 | P5: 147 | Q5: 140 | R5: 133 | S5: 126 | T5: 119 | U5: 112 | V5: 105 | W5: 98 | X5: 91 | Y5: 84 | Z5: 77
A6: MISTO | B6: DIAMANTE | C6: 1200 | D6: 8 | E6: 10 | F6: 248 | G6: 240 | H6: 232 | I6: 224 | J6: 216 | K6: 208 | L6: 200 | M6: 192 | N6: 184 | O6: 176 | P6: 168 | Q6: 160 | R6: 152 | S6: 144 | T6: 136 | U6: 128 | V6: 120 | W6: 112 | X6: 104 | Y6: 96 | Z6: 88
A7: PENDENCIA | B7: PRATA | C7: 300 | D7: 6 | E7: 4 | F7: 186 | G7: 180 | H7: 174 | I7: 168 | J7: 162 | K7: 156 | L7: 150 | M7: 144 | N7: 138 | O7: 132 | P7: 126 | Q7: 120 | R7: 114 | S7: 108 | T7: 102 | U7: 96 | V7: 90 | W7: 84 | X7: 78 | Y7: 72 | Z7: 66
A8: PENDENCIA | B8: OURO | C8: 600 | D8: 7 | E8: 6 | F8: 217 | G8: 210 | H8: 203 | I8: 196 | J8: 189 | K8: 182 | L8: 175 | M8: 168 | N8: 161 | O8: 154 | P8: 147 | Q8: 140 | R8: 133 | S8: 126 | T8: 119 | U8: 112 | V8: 105 | W8: 98 | X8: 91 | Y8: 84 | Z8: 77
A9: PENDENCIA | B9: PLATINA | C9: 900 | D9: 8 | E9: 8 | F9: 248 | G9: 240 | H9: 232 | I9: 224 | J9: 216 | K9: 208 | L9: 200 | M9: 192 | N9: 184 | O9: 176 | P9: 168 | Q9: 160 | R9: 152 | S9: 144 | T9: 136 | U9: 128 | V9: 120 | W9: 112 | X9: 104 | Y9: 96 | Z9: 88
A10: PENDENCIA | B10: DIAMANTE | C10: 1200 | D10: 9 | E10: 10 | F10: 279 | G10: 270 | H10: 261 | I10: 252 | J10: 243 | K10: 234 | L10: 225 | M10: 216 | N10: 207 | O10: 198 | P10: 189 | Q10: 180 | R10: 171 | S10: 162 | T10: 153 | U10: 144 | V10: 135 | W10: 126 | X10: 117 | Y10: 108 | Z10: 99
A11: MISTO COND. | B11: PRATA | C11: 600 | D11: 3.5 | E11: 4 | F11: 108.5 | G11: 105 | H11: 101.5 | I11: 98 | J11: 94.5 | K11: 91 | L11: 87.5 | M11: 84 | N11: 80.5 | O11: 77 | P11: 73.5 | Q11: 70 | R11: 66.5 | S11: 63 | T11: 59.5 | U11: 56 | V11: 52.5 | W11: 49 | X11: 45.5 | Y11: 42 | Z11: 38.5
A12: MISTO COND. | B12: OURO | C12: 900 | D12: 4.5 | E12: 6 | F12: 139.5 | G12: 135 | H12: 130.5 | I12: 126 | J12: 121.5 | K12: 117 | L12: 112.5 | M12: 108 | N12: 103.5 | O12: 99 | P12: 94.5 | Q12: 90 | R12: 85.5 | S12: 81 | T12: 76.5 | U12: 72 | V12: 67.5 | W12: 63 | X12: 58.5 | Y12: 54 | Z12: 49.5
A13: MISTO COND. | B13: PLATINA | C13: 1200 | D13: 5.5 | E13: 8 | F13: 170.5 | G13: 165 | H13: 159.5 | I13: 154 | J13: 148.5 | K13: 143 | L13: 137.5 | M13: 132 | N13: 126.5 | O13: 121 | P13: 115.5 | Q13: 110 | R13: 104.5 | S13: 99 | T13: 93.5 | U13: 88 | V13: 82.5 | W13: 77 | X13: 71.5 | Y13: 66 | Z13: 60.5
A14: MISTO COND. | B14: DIAMANTE | C14: 1500 | D14: 6.5 | E14: 10 | F14: 201.5 | G14: 195 | H14: 188.5 | I14: 182 | J14: 175.5 | K14: 169 | L14: 162.5 | M14: 156 | N14: 149.5 | O14: 143 | P14: 136.5 | Q14: 130 | R14: 123.5 | S14: 117 | T14: 110.5 | U14: 104 | V14: 97.5 | W14: 91 | X14: 84.5 | Y14: 78 | Z14: 71.5
... A26: PEND. COND. | B26: DIAMANTE | C26: 1500 | D26: 7.5 | E26: 10 | F26: 232.5 | G26: 225 | H26: 217.5 | I26: 210 | J26: 202.5 | K26: 195 | L26: 187.5 | M26: 180 | N26: 172.5 | O26: 165 | P26: 157.5 | Q26: 150 | R26: 142.5 | S26: 135 | T26: 127.5 | U26: 120 | V26: 112.5 | W26: 105 | X26: 97.5 | Y26: 90 | Z26: 82.5

Sheet CPF
A2: Nome | B2: Matrícula | C2: Empresa | D2: Cpf
A3: ALAN FEITOSA DE SOUTO | B3: 000262 | C3: G INFO | D3: 646.525.643-68
A4: ANTONIO MARCOS LIMA DA SILVA | C4: G INFO | D4: 009.280.143-98
A5: BRUNO MATIAS DA SILVA | C5: G INFO | D5: 070.863.133-94
A6: CLAUDIANO CICINATO DA SILVA | C6: G INFO | D6: 026.126.893-70
A7: DJONATHA COSTA DA SILVA | C7: G INFO | D7: 112.311.524-94
A8: ELISANGELA BOTELHO DA ROCHA | C8: G INFO | D8: 664.730.393-68
A9: ELISSON PEREIRA COUTINHO NOVAIS | C9: G INFO | D9: 078.114.013-71
A10: FABIO SILVESTRE BRITO | B10: 000115 | C10: G INFO | D10: 002.590.223-73
A11: FRANCISCO CARLOS EUGENIO DO NASCIMENTO | B11: 000333 | C11: G INFO | D11: 045.179.853-85
A12: FRANCISCO DAS CHAGAS E SILVA ROCHA | B12: 000216 | C12: G INFO | D12: 604.677.683-07
A13: FRANCISCO DIEGO ALVES FERREIRA | B13: 000295 | C13: G INFO | D13: 065.966.543-38
A14: FRANCISCO HELIO MARINHO CUNHA NETO | C14: G INFO | D14: 078.519.483-55
A15: FRANCISCO LUCAS SOUSA CUNHA | B15: 000305 | C15: G INFO | D15: 625.648.953-52
A16: GABRIEL MARTINS MUNIZ | B16: 000318 | C16: G INFO | D16: 078.282.793-45
A17: GEILSON DA SILVA MOURA | C17: G INFO | D17: 070.629.143-39
A18: GILVAN ASSUNCAO SILVA | B18: 000343 | C18: G INFO | D18: 019.738.393-93
A19: GLEISON VALENTIM ARAUJO | C19: G INFO | D19: 075.630.503-96
A20: GUTEMBERGUE OLIVEIRA | B20: 000271 | C20: G INFO | D20: 020.305.163-76
A21: HALLEF GUILHERME LIMA CLEMENTE SILVA | C21: G INFO | D21: 077.115.853-06
A22: IRINETO FERREIRA DE AGUIAR | B22: 000217 | C22: G INFO | D22: 033.727.593-97
A23: JOAO PAULO GOUVEIA DA SILVA | C23: G INFO | D23: 891.107.223-00
A24: JOSE AMAURY BORGES FILHO | C24: G INFO | D24: 068.959.103-95
A25: JOSE MARIA DA COSTA LEONARDO | B25: 000221 | C25: G INFO | D25: 734.146.113-68
A26: LUCAS SOUZA SILVA | C26: G INFO | D26: 074.800.793-89
A27: LUCIEUDO BANDEIRA ALVES FILHO | B27: 000320 | C27: G INFO | D27: 074.418.063-56
A28: LUIZ CARLOS MACHADO MACIEL | C28: G INFO | D28: 058.715.743-78
A29: MAILSON FRANCISCO PEREIRA | C29: G INFO | D29: 062.780.033-50
A30: MARCOS PEREIRA CARVALHO FILHO | C30: G INFO | D30: 073.501.783-28
A31: MARCOS VICTOR LOPES MEDEIROS FONSECA | C31: G INFO | D31: 034.029.363-21
A32: PAULO ROBERTO ARAUJO GALVAO | C32: G INFO | D32: 014.069.373-47
A33: PEDRO DA SILVA MAIA | C33: G INFO | D33: 092.106.483-74
A34: ROBSON BEZERRA DA SILVA | C34: G INFO | D34: 619.340.993-92
A35: ROMARIO NOBRE DE MELO | B35: 000336 | C35: G INFO | D35: 051.728.733-17
A36: RONALD MESQUITA DOS SANTOS | C36: G INFO | D36: 107.099.153-81
A37: THIAGO CASTRO DO NASCIMENTO | C37: G INFO | D37: 086.965.763-14
A38: VALDERILO FERREIRA LIMA JUNIOR | B38: 000293 | C38: G INFO | D38: 082.974.113-54
A39: WESLLEY ALVES UCHOA | B39: 000119 | C39: G INFO | D39: 083.598.453-28
A40: WILLIAM ADRIANO DANTAS | B40: 000116 | C40: G INFO | D40: 070.038.853-28
A41: YVINA CHAGAS ALENCAR | C41: G INFO | D41: 080.135.683-00
...

Sheet CONCLUIDAS
A1: protocolo | B1: cliente | C1: status_solicitacao | D1: tipo_solicitacao | E1: tipo_rua | F1: rua | G1: numero | H1: cidade | I1: bairro | J1: latitude | K1: longitude | L1: atendente | M1: atendente_origem | N1: data_abertura | O1: data_prazo | P1: data_encerramento | Q1: data_primeiro_relato_encerramento | R1: em_atraso | S1: dias_atraso | T1: cat_2 | U1: cat_3 | V1: cat_4 | W1: cat_5 | X1: solucao | Y1: tecnico_original | Z1: protocolo_original | AA1: olt | AB1: relato_encerramento | AC1: descricao_abertura
A2: 3780562 | B2: ERICK FERREIRA DA SILVA | C2: Encerramento | D2: RETIRADA DE EQUIPAMENTOS | E2: Rua | F2: Rua Visconde do Rio Branco | G2: 8 | H2: Palmares | I2: São Sebastião | J2: -8.6877621e+15 | K2: -3559317156 | L2: KELVER EDUARDO GOMES SOBRAL | M2: ESTEFANY SILVA ARARIPE | N2: 46220 | O2: 46235 | P2: 46281 | Q2: 46281 | R2: Sim | S2: 46 | T2: Retirada de Equipamentos | X2: Equipamento Entregue | AB2: *TEC:* KELVER EDUARDO *DATA: 16/09/2026**COD RETIRADA* 3780562*NOME DO CLIENTE* ERICK FERREIRA DA SILVA*DESCRIÇÃO:* RETIRADA DE EQUIPAMENTO.*SOLUÇÃO:* EQUIPEMENTO NAO RETIRADO. *OBS* EM CONTATO COM CLIENTE O MESMO INFORMOU QUE IRÁ PROCURAR O EQUIPAMENTO , AFIRMOU NAO SABER ONDE COLOCOU , DISSE TAMBEM QUE ASSIM QUE ACHAR ENTREGARÁ EM LOJA.Dispositivo: samsung SM-A146MVersão do Android: 15Versão do V·Tasks: 5.9.214 Status alterado de Andamento para Encerramento | AC2: 1. DESCRIÇÃO DA SOLICITAÇÃO:2.CONTATO TELEFÔNICO (01):3.CONTATO TELEFÔNICO (02):4.WHATSAPP:5.PONTO DE REFERÊNCIA:6.DISPONIBILIDADE:7.PRAZO: 10 DIAS CORRIDOS8. CLIENTE COM NECESSIDADES ESPECIAIS/NECESSIDADE?Contrato cancelado, necessário realizar visita ao cliente para remover os equipamentos em comodato.ONT ZTE 2 ANTENAS V9.0
A3: 3819617 | B3: JOSEFINA JULIA LIRA PORTELA | C3: Encerramento | D3: RETIRADA DE EQUIPAMENTOS | E3: Rua | F3: Rua Diário De Pernambuco | G3: 335 | H3: Palmares | I3: Modelo | J3: -86861283 | K3: -355971726 | L3: TARCIO FRANCISCO DA SILVA | M3: SARA ALLANA RODRIGUES FERNANDES | N3: 46247 | O3: 46248 | P3: 46283 | Q3: 46283 | R3: Sim | S3: 35 | T3: Retirada de Equipamentos | X3: Equipamento Entregue | AB3: *TEC:* TARCIO FRANCISCO *DATA: 18/09/2026**COD RETIRADA* 3819617*NOME DO CLIENTE* JOSEFINA JULIA LIRA PORTELA*ENDEREÇO* Rua Diário De Pernambuco, 335, Modelo - Palmares*DESCRIÇÃO:* RETIRADA DE EQUIPAMENTO*SOLUÇÃO:* EQUIPEMENTO RETIRADO (GPON00EE5C2C)*OBS*Dispositivo: Xiaomi 23053RN02AVersão do Android: 15Versão do V·Tasks: 5.9.215 Status alterado de Andamento para Encerramento | AC3: 1. DESCRIÇÃO DA SOLICITAÇÃO:2.CONTATO TELEFÔNICO (01):3.CONTATO TELEFÔNICO (02):4.WHATSAPP:5.PONTO DE REFERÊNCIA:6.DISPONIBILIDADE:7.PRAZO: 10 DIAS CORRIDOS8. CLIENTE COM NECESSIDADES ESPECIAIS/NECESSIDADE?Contrato cancelado, necessário realizar visita ao cliente para remover os equipamentos em comodato.ONT HG325AX
A4: 3822864 | B4: FÁBIO CAXIAS DE CARVALHO | C4: Encerramento | D4: PENDÊNCIA FIBRA - COND. | E4: Rua | F4: Rua Tomaz de Aquino | G4: 484 | H4: Aquiraz | I4: Centro | L4: HALLEF GUILHERME LIMA CLEMENTE SILVA | M4: FRANCISCA ALICE MESQUITA FERREIRA | N4: 46249 | O4: 46250 | P4: 46269 | Q4: 46269 | R4: Sim | S4: 19 | T4: Cliente Condomínio | U4: Pendência | V4: LOS | W4: Fibra Sem Sinal / Luz Los Vermelha | X4: Troca Conector - Desgastado | AA4: OLT Aquiraz VLAN 12 | AB4: *PENDÊNCIA**Data:* 04/09/2026 *ATENDENTE:**Técnico:* Hallef / Ismael *CLIENTE* FÁBIO CAXIAS DE CARVALHO*ENDEREÇO* Condomínio Mirante da Prainha,Casa 44*Caixa:*8767*Porta:* 5*Potência da Caixa:* -22*Potência do Cliente:*-22*Serviço* Troca de drop, cortado por outra provedora Conexão normalizada pós troca *Materiais* *conector azul:* 1und *conector verde:* 1und *Fixa fio* *adesivo* 1und *canaleta**RJ 45**EQUIPAMENTOS**ONT*: *ROTEADOR* *ONU**DROP**Início* 1000m*Fim* 860m*Utilizado* 140m *EQUIPAMENTO RECOLHIDO**Valor:**Obs.:*Dispositivo: Xiaomi 2311DRK48IVersão do Android: 16Versão do V·Tasks: 5.9.213 Status alterado de Reagendado para Encerramento | AC4: 15/08/2026 - 16:59 01. RELATO DO CLIENTE: Cliente relata sem internet / offline no voalle / link los no UNM / piscando vermelho no equipamento02. ANÁLISE SISTEMA (UNM): linklos no UNM03. ANÁLISE SISTEMA (VOALLE): offline no Voalle04. EXTRATO COM QUEDAS: XX05. GERENCIAMENTO REM. HABILITADO: XX06. PROCEDIMENTO REALIZADO: REBOOT DA TOMADA07. POTÊNCIA: XX08. CAIXA E PORTA: CX 8767 P-0508. CONTATO: 8599801223809. ENDEREÇO COMPLETO: Rua Tomaz de Aquino 484, Centro - Aquiraz, CE61700-00010. CONDOMÍNIO: CONDOMINIO MIRANTE DA PRAINHA 10. PONTO DE REFERÊNCIA: MIRANTE DA PRAINHA 11. DISPONIBILIDADE: DOMINGO O DIA TODO12. OBSERVAÇÃO: ENTRAR EM CONTATO ANTES DE IR AO LOCAL
A5: 3835168 | B5: FATIMA MARIA SILVA | C5: Encerramento | D5: INSTALAÇÃO FIBRA - PF | E5: Avenida | F5: Av. Laureano de Paulo Santana | G5: 663 | H5: Cascavel | I5: Caponga | J5: -4040241 | K5: -381964008 | L5: ISRAEL OLIVEIRA MORAIS | M5: MARIA ANTONIA ABREU NEVES | N5: 46256 | O5: 46257 | P5: 46269 | Q5: 46269 | R5: Sim | S5: 12 | T5: Cliente Pessoa Física | U5: Instalação | X5: Troca Conector - Desgastado | AA5: OLT Caponga VLAN 1005 | AB5: ⚠️ *instalação* ⚠️*Data:* 04/09 /2026*TÉCNICO RESPONSÁVEL:* Israel Oliveira*CLIENTE:* FATIMA MARIA SILVA*ENDEREÇO:* Av. Laureano de Paulo Santana, 663, Caponga - Cascavel*LOCALIZAÇÃO DO CLIENTE*-4.040496,-38.196510*SUPORTE N2:* *CAIXA:* 1591*PORTA:* 01*POTÊNCIA DA CAIXA:* -20*POTÊNCIA DO CLIENTE:* -21*ACESSO REMOTO HABILITADO:* sim*SENHA DO ROTEADOR:**SERVIÇO:* instalação fibra realizada com sucesso.*OBS:* *MATERIAL UTILIZADO:*02 conector verde02 fixa fio.01 canaleta.75m de drop.01 Ont Intelbras ax3000 mac:EE56*VALOR:* 0,00 *DROP INICIAL:* 765*DROP FINAL:* 690*METRAGEM TOTAL:* 75*CLASSIFICAÇÃO DE ENCERRAMENTO :* finalizado✅Dispositivo: samsung SM-A075MVersão do Android: 16Versão do V·Tasks: 5.9.213 Status alterado de Agendado para Encerramento | AC5: VENDEDOR: maria antoniaÁREA: PAP () CALL-CENTER ( ) LOJA ( ) TBR (x )TITULAR: FATIMA MARIA SILVATELEFONE: WHATSAPP: 85 99919-668385996488726DISPONIBILIDADE: MANHA( x) TARDE ( ) DIA TODO ()DATA:CIDADE E BAIRRO: Caponga, Cascavel PLANO: 500mb 99,99VALOR ORIGINAL DO PLANO: POSSUI DESCONTO DE PONTUALIDADE? SIM ( ) NÃO ( x)SE SIM: D5 ( ) ou DNET - D10( )DESCONTO DE __ , SE PAGO ATÉ O VENCIMENTO POR 12 MESESTAXA INSTALAÇÃO: ATENDIMENTO REGISTRADO:Google Drive ( ) Fortics ( ) Smart (x )FIDELIDADE: (x ) SIM NÃO ( )CLIENTE DESEJA NOTA FISCAL: SIM ( ) NÃO (x )COORD: -4.040166080710224, -38.19631497485019CAIXA: 1591CASA DUPLEX ( ) CASA TERREA (x)QUANTOS E QUAIS APARELHOS CONECTADOS:Celulares mais smarte TV notebook etc.OBSERVAÇÃO ADICIONAL:Ativação do contrato: 173795---- Endereço de Instalação ----CEP: 62850-000Logradouro: Av. Laureano de Paulo SantanaNúmero: 663Bairro: CapongaEstado: CECidade: CascavelComplemento: casaReferência: prox a Padaria nossa senhora de Fátima---- Serviços a serem ativados ----- 0422 - IFT - ULTRAINFO - 500MB
A6: 3837312 | B6: ERIVALDA MARIA DA SILVA | C6: Encerramento | D6: RETIRADA DE EQUIPAMENTOS | E6: Quadra | F6: Quadra 13 | G6: 32 | H6: Palmares | I6: Quilombo 2 | J6: -8702848 | K6: -35596849 | L6: TARCIO FRANCISCO DA SILVA | M6: LUCAS DURVAL DAMASCENO SILVA | N6: 46258 | O6: 46261 | P6: 46283 | Q6: 46283 | R6: Sim | S6: 22 | T6: Retirada de Equipamentos | X6: Equipamento Entregue | AB6: *TEC:* TARCIO FRANCISCO *DATA: 18/09/2026**COD RETIRADA* 3837312*DESCRIÇÃO:* RETIRADA DE EQUI sóPAMENTOS*NOME* ERIVALDA MARIA DA SILVA*SOLUÇÃO:* equipamento retirado*ENDEREÇO* Quadra 13, 32, Quilombo 2 - Palmares*ONT XPON DUAL-BAND AC1200*(DO5FAF7D5E1D)*OBS*Dispositivo: Xiaomi 23053RN02AVersão do Android: 15Versão do V·Tasks: 5.9.215 Status alterado de Andamento para Encerramento | AC6: 1. DESCRIÇÃO DA SOLICITAÇÃO:2.CONTATO TELEFÔNICO (01):3.CONTATO TELEFÔNICO (02):4.WHATSAPP:5.PONTO DE REFERÊNCIA:6.DISPONIBILIDADE:7.PRAZO: 10 DIAS CORRIDOS8. CLIENTE COM NECESSIDADES ESPECIAIS/NECESSIDADE?Contrato cancelado, necessário realizar visita ao cliente para remover os equipamentos em comodato.ONT XPON DUAL-BAND AC1200
A7: 3839231 | B7: REGINA CELIA PEREIRA LIMA BARBOSA | C7: Encerramento | D7: DNET - PENDÊNCIA FIBRA - COND. | E7: Rua | F7: RUA CAMPOS FILHO | G7: 167 | H7: Maracanaú | I7: CAGADO | J7: -3.8437576e+16 | K7: -3.8637581e+15 | L7: CARLOS HENRIQUE LINO SILVA | M7: JOSE MATEUS RICARDO SERPA | N7: 46259 | O7: 46260 | P7: 46266 | Q7: 46266 | R7: Sim | S7: 6 | T7: DNET - Cliente Condomínio | U7: DNET - Pendência | V7: DNET - LOS | W7: DNET - Fibra Sem Sinal / Luz Los Vermelha | X7: Troca Conector - Desgastado | AA7: OLT DNET TEMPORARIO | AB7: Abertura Solicitação para visita técnica no cliente, a pedido do mesmo.CLIENTE NORMALIZOU APOS MANUTENÇÃO DA INFRAESTRUTURA. Dispositivo: samsung SM-A055MVersão do Android: 14Versão do V·Tasks: 5.9.211 Status alterado de Tratamento Infra para Encerramento | AC7: 25/08/2026 - 13:37 01. RELATO DO CLIENTE: DNET - Fibra Sem Sinal / Luz Los Vermelha02. ANÁLISE SISTEMA (UNM): offline 03. ANÁLISE SISTEMA (VOALLE): offline 04. EXTRATO COM QUEDAS: xxxx05. GERENCIAMENTO REM. HABILITADO: verificar 06. PROCEDIMENTO REALIZADO: nenhum cliente retenção07. POTÊNCIA: sem08. CAIXA E PORTA: sem08. CONTATO: 85 988665595 98844789109. ENDEREÇO COMPLETO: Rua vamos filho 167 Condomínio Virgílio tavaro 210. CONDOMÍNIO: SIM 10. PONTO DE REFERÊNCIA: Piso novo /BLOCO 10 AP 20411. DISPONIBILIDADE: total12. OBSERVAÇÃO:
A8: 3839677 | B8: RONILSON ALVES DA SILVA | C8: Encerramento | D8: RETIRADA DE EQUIPAMENTOS | E8: Rua | F8: Rua Doutor Costa Lima | G8: 30 | H8: Palmares | I8: Santo Onofre | J8: -86795889 | K8: -355842531 | L8: TARCIO FRANCISCO DA SILVA | M8: ESTEFANY SILVA ARARIPE | N8: 46259 | O8: 46260 | P8: 46283 | Q8: 46283 | R8: Sim | S8: 23 | T8: Retirada de Equipamentos | X8: Equipamento Entregue | AB8: *TEC:* TARCIO FRANCISCO *DATA: 18/09/2026**COD RETIRADA* 3839677*DESCRIÇÃO* RETIRADA DE EQUIPAMENTOS*NOME* RONILSON ALVES DA SILVA*SOLUÇÃO:* equipamentos retirado*ENDEREÇO* Rua Doutor Costa Lima, 30, Santo Onófre - Palmares*ONT ZTE 2 ANTENAS* (ZTEGD4B328EF)Dispositivo: Xiaomi 23053RN02AVersão do Android: 15Versão do V·Tasks: 5.9.215 Status alterado de Andamento para Encerramento | AC8: 1. DESCRIÇÃO DA SOLICITAÇÃO:2.CONTATO TELEFÔNICO (01):3.CONTATO TELEFÔNICO (02):4.WHATSAPP:5.PONTO DE REFERÊNCIA:6.DISPONIBILIDADE:7.PRAZO: 10 DIAS CORRIDOS8. CLIENTE COM NECESSIDADES ESPECIAIS/NECESSIDADE?Contrato cancelado, necessário realizar visita ao cliente para remover os equipamentos em comodato.ONT ZTE 2 ANTENAS V9.0
A9: 3839959 | B9: JOISE NUNES DE OLIVEIRA | C9: Encerramento | D9: PENDÊNCIA FIBRA POTÊNCIA ALTA | E9: Rua | F9: Rua José Carneiro de Andrade | G9: 156 | H9: Choró | I9: Cidade Nova | L9: ANTONIO TIAGO AMANCIO DA SILVA | M9: EMILY LUANY ALVES BASTOS | N9: 46259 | O9: 46260 | P9: 46267 | Q9: 46267 | R9: Sim | S9: 7 | T9: Cliente Pessoa Física | U9: Pendência | V9: Potência Alta | W9: Correção de Potência | X9: Troca Conector - Desgastado | AA9: OLT Choro VLAN 4004 | AB9: ♦️ *PENDÊNCIA* ♦️*Data:* 02/09/2026*Técnico:* Tiago*Auxiliar:* Amaury *Cliente:* JOISE NUNES DE OLIVEIRA*Endereço:* Rua José Carneiro de Andrade, 156, Cidade Nova *Classificação de Encerramento:*RESOLVIDO"CLIENTE RELATA QUE DURANTE O DIA A INTERNET É BOA, POREM A NOITE NÃO TA FUNCIONANDO LEGAL, CLIENTE AFIRMA QUE DURANTE A NOITE A INTERNET FICA CAINDO"Dispositivo: Xiaomi 23100RN82LVersão do Android: 15Versão do V·Tasks: 5.9.211 Status alterado de Andamento para Encerramento | AC9: 25/08/2026 - 20:12 01. RELATO DO CLIENTE: cliente com potência alta, necessário normalizar a potência02. ANÁLISE SISTEMA (UNM): online03. ANÁLISE SISTEMA (VOALLE): Online04. EXTRATO COM QUEDAS: SIM ou NÃO x05. GERENCIAMENTO REM. HABILITADO: SIM ou NÃO, verificar xx06. PROCEDIMENTO REALIZADO: visto a potência no unm07. POTÊNCIA: -16.0708. CAIXA E PORTA: cx1095 p0208. CONTATO: 889931426068899362037809. ENDEREÇO COMPLETO: Rua José Carneiro de Andrade, 156 - Cidade Nova - Choró - CE - CEP 63950-00010. CONDOMÍNIO: SIM (Nome) ou NÃO x10. PONTO DE REFERÊNCIA: Perto Do Hospital11. DISPONIBILIDADE: o dia todo 12. OBSERVAÇÃO:
A10: 3840367 | B10: FRANCISCO AURICLECIO QUEIROZ DE SOUZA | C10: Encerramento | D10: INSTALAÇÃO FIBRA - COND. | E10: Rua | F10: Rua Benjamim Barreto | G10: 73 | H10: Fortaleza | I10: Cristo Redentor | J10: -3705679 | K10: -38566873 | L10: FRANCISCO JHONATA DA COSTA | M10: DANIEL DA SILVA COSTA | N10: 46260 | O10: 46261 | P10: 46267 | Q10: 46267 | R10: Sim | S10: 6 | T10: Cliente Condomínio | U10: Instalação | X10: Troca Conector - Desgastado | AA10: OLT Barra do Ceará VLAN 1001 | AB10: *INSTALAÇÃO**Data* 02/09/2026*Técnico* Jhonata Costa CLIENTE:FRANCISCO AURICLECIO QUEIROZ DE SOUZAENDERECO:Rua Benjamim Barreto, 73, Cristo Redentor - Fortaleza*Caixa:4378*Porta*:04*SINAL DA CAIXA*. -22*SINAL DO CLIENTE:-24*SERVICO REALIZADO*Instalação concluída com sucesso...*Material utilizado*02Conector Verde 00Conector Azul02Fixa fio00 Canaleta00 Esticador00Adesivo conector0 RJ4500 pat Cord01 ONT FIBERHOME *OBS* : Concluído okLogin:multipro Senha:multipro *VALOR* :*Cabo inicial*:*Cabo final* *Metragem* *Drop inicial*1000*Drop final* : 0697*Metragem**0303Dispositivo: samsung SM-A075MVersão do Android: 16Versão do V·Tasks: 5.9.206 Status alterado de Reagendado para Encerramento | AC10: VENDEDOR: DANIEL ÁREA: PAP (X) CALL-CENTER ( ) LOJA ( ) TBR ( )TITULAR: FRANCISCO AURICLECIO QUEIROZ DE SOUZA TELEFONE: 85999133956WHATSAPP: 85999133956DISPONIBILIDADE: MANHA( ) TARDE ( x) DIA TODO ()DATA:CIDADE E BAIRRO: CRISTO REDENTOR FORTALEZA PLANO: 500 CURUJÃO VALOR ORIGINAL DO PLANO: 99.99POSSUI DESCONTO DE PONTUALIDADE? SIM ( x) NÃO ( )SE SIM: D5 ( ) ou DNET - D10( )DESCONTO DE __ , SE PAGO ATÉ O VENCIMENTO POR 12 MESESTAXA INSTALAÇÃO: ATENDIMENTO REGISTRADO:Google Drive ( ) Fortics ( ) Smart ( )FIDELIDADE: ( x) SIM NÃO ( )CLIENTE DESEJA NOTA FISCAL: SIM ( ) NÃO ( )COORD:CAIXA: -3.7056938, -38.5668779CX6166CASA DUPLEX ( x) CASA TERREA ()QUANTOS E QUAIS APARELHOS CONECTADOS: 4 CELULARES OBSERVAÇÃO ADICIONAL:Ativação do contrato: 173980---- Endereço de Instalação ----CEP: 60337-390Logradouro: Rua Benjamim BarretoNúmero: 73Bairro: Cristo RedentorEstado: CECidade: FortalezaComplemento: AILOS---- Serviços a serem ativados ----- 0422 - ULTRAINFO - 500MB
A11: 3840771 | B11: FRANCISCO MOYSES FREITAS DA SILVA | C11: Encerramento | D11: DNET - PENDENCIA FIBRA - PF | E11: Avenida | F11: Avenida Noé Leite de Freitas | G11: 15 | H11: Aquiraz | I11: Altos dos Pereiras | J11: -3914746 | K11: -384271461 | L11: ANDRE SILVA LOIOLA | M11: RUAN VICTOR SANTOS SOUZA CLARINDO | N11: 46260 | O11: 46261 | P11: 46266 | Q11: 46266 | R11: Sim | S11: 5 | T11: DNET - Cliente Pessoa Física | U11: DNET - Pendência | V11: DNET - Configuração Equipamentos | W11: DNET - Configuração Básica | X11: Troca Conector - Desgastado | AA11: OLT DNET TEMPORARIO | AB11: Abertura Solicitação para visita técnica no cliente, a pedido do mesmo.NORMALIZADO PÓS INFRA.Dispositivo: motorola moto g23Versão do Android: 14Versão do V·Tasks: 5.9.211 Status alterado de Tratamento Infra para Encerramento | AC11: 26/08/2026 - 12:44 01. RELATO DO CLIENTE: Cliente informa que está sem conexão há 8 dias e relata que há uma LED vermelha piscando no equipamento. Foi verificado em sistema que o serviço consta como normal e que o cliente está com conexão ativa. O cliente informou que o equipamento está instalado na residência de seu pai e que, no momento do atendimento, não se encontrava no local. Dessa forma, não foi possível realizar os procedimentos padrões nem verificar presencialmente o status da conexão e do equipamento.02. ANÁLISE SISTEMA (UNM): Não localizado03. ANÁLISE SISTEMA (VOALLE): ONLINE04. EXTRATO COM QUEDAS: NÃO05. GERENCIAMENTO REM. HABILITADO: NÃO, habilitar por favor06. PROCEDIMENTO REALIZADO: não foi possível fazer pois cliente não estava no local07. POTÊNCIA: xx08. CAIXA E PORTA:xx08. CONTATO: (85)99675-503509. ENDEREÇO COMPLETO: Rua Maria Liberalina, 0 - Alto dos Pereiras - Aquiraz - CE - CEP 61700-000/ Forrozão 200010. CONDOMÍNIO: NÃO10. PONTO DE REFERÊNCIA: Casa do moyses Freitas 11. DISPONIBILIDADE: Total12. OBSERVAÇÃO: O mesmo está ciente de cobranças a serem geradas caso a visita seja improdutiva
A12: 3840799 | B12: IRIS PEREIRA GOMES | C12: Encerramento | D12: PENDÊNCIA FIBRA DEFINIR PRAZO | E12: Rua | F12: R. Itapipoca | G12: 80 | H12: Cascavel | I12: Caponga | J12: -40450043 | K12: -381897219 | L12: ISRAEL OLIVEIRA MORAIS | M12: ANA CAROLINE GIRAO LIMA | N12: 46260 | O12: 46281 | P12: 46270 | Q12: 46270 | R12: Não | T12: Cliente Pessoa Física | U12: Pendência | V12: Definir Prazo | W12: Definir Prazo | X12: Troca Conector - Desgastado | AA12: OLT Caponga VLAN 1005 | AB12: ⚠️ *pendência* ⚠️*Data:* 05/09/2026*TÉCNICO RESPONSÁVEL:* Israel Oliveira *CLIENTE:* IRIS PEREIRA GOMES*ENDEREÇO:* R. Itapipoca, 80, Caponga - Cascavel*LOCALIZAÇÃO DO CLIENTE* -4.044932,-38.190190*SUPORTE N2:* *CAIXA:* 1654*PORTA:* 08*POTÊNCIA DA CAIXA:* -24*POTÊNCIA DO CLIENTE:* -25*ACESSO REMOTO HABILITADO:* sim*SENHA DO ROTEADOR:**SERVIÇO:* drop rompido, realizado a troca do drop e voltou o acesso.*OBS:* *MATERIAL UTILIZADO:*02 conector verde.190m de drop.*VALOR:* 0,00 *DROP INICIAL:* 190*DROP FINAL:* 0*METRAGEM TOTAL:* 190*CLASSIFICAÇÃO DE ENCERRAMENTO :* finalizado ✅Dispositivo: samsung SM-A075MVersão do Android: 16Versão do V·Tasks: 5.9.213 Status alterado de Agendado para Encerramento | AC12: 26/08/2026 - 12:15 01. RELATO DO CLIENTE: sem internet, led vermelha no equipamento02. ANÁLISE SISTEMA (UNM): loss03. ANÁLISE SISTEMA (VOALLE): off04. EXTRATO COM QUEDAS: SIM ou NÃO05. GERENCIAMENTO REM. HABILITADO: SIM ou NÃO06. PROCEDIMENTO REALIZADO: tirou da tomada07. POTÊNCIA: xx08. CAIXA E PORTA: 1654/0108. CONTATO: (85)99975-9911-(85)98476-014509. ENDEREÇO COMPLETO: R. Itapipoca, 80 - Caponga - Cascavel - CE - CEP 62850000 - casa10. CONDOMÍNIO: SIM (Nome) ou NÃO10. PONTO DE REFERÊNCIA: Rua de Frente com o Hotel Jangadas11. DISPONIBILIDADE: AO SÁBADO DIA 1512. OBSERVAÇÃO: REABERTURA SOLICITADO PELA GESTÃO DE O.S
A13: 3840858 | B13: DAVID ARAUJO ABREU | C13: Encerramento | D13: SERVIÇO - COND. | E13: Rua | F13: RUA INDUSTRIAL AMILCAR ARAUJO | G13: 856 COND. PORTAL DE LION CASA 2 | H13: Eusébio | I13: COITÉ | J13: -38828104 | K13: -3846853 | L13: PAULO ROBERTO ARAUJO GALVAO | M13: LARISSA MOURA DAS NEVES | N13: 46260 | O13: 46263 | P13: 46266 | Q13: 46266 | R13: Sim | S13: 3 | T13: Cliente Condomínio | U13: Serviço | V13: Realocação de Equipamento | W13: Taxa Faturada | X13: Troca Conector - Desgastado | AA13: OLT Eusébio 2 VLAN 58 | AB13: 🚧⚠️ *SERVIÇO* ⚠️🚧*Chegada**Saída**Data* 01.09.2026*SUPORTE**COMERCIAL* *Técnico* Paulo Roberto / Felipe Soares *Cliente* DAVID ARAUJO ABREU*Endereço* RUA INDUSTRIAL AMILCAR ARAUJO, 856 COND. PORTAL DE LION CASA 2, COITÉ - Eusébio*obs sobre o endereço* COND. PORTAL DE LION CASA 2*CONTATO* *Caixa* 6317*PORTA* 09*SINAL DO CAIXA*-21*SINAL DO CLIENTE*-22*Velocidade* *Material utilizado*1 Conector Verde 1 Conector Azul6 Fixa fixo 0 canaleta0 Esticado1 adesivo 0 Per Cord0 RJ45PROBLEMA RELATADO: OBS. Realizada visita técnica para realocação de equipamento.Equipamento realocado para onde o cliente pediu.*TAXA: R$75,00 em 2X*Cabo de redeInicial Final Metragem *SENHA DO EQUIPAMENTO**Equipamento anterior**Equipamento Atual* *MEC* *Drop inicial* 292*Drop Final* 200*Metragem* 092*Classificação de Encerramento*RESOLVIDO✅Dispositivo: motorola moto g04sVersão do Android: 14Versão do V·Tasks: 5.9.203 Status alterado de Andamento para Encerramento | AC13: 26/08/2026 - 13:10 1.SOLICITAÇÃO: deseja realocar o equipamento para outro cômodo3.CONTATO TELEFÔNICO (01): 85994195404FONE 02(WHATSAPP) 859941954044.E-MAIL: CONTACT@ARAUJODAVID.COM5.WHATSAPP: 859941954046.PONTO DE REFERÊNCIA: Rua Industrial Amilcar Araujo 856, Casa 2 / Cond. Portal de Lion // Entrando na rua do Colégio Antares7.DISPONIBILIDADE: o dia todo8.VALOR DO SERVIÇO / FORMA DE PAGAMENTO E VALORES: R$75,00 em 2x9.PRAZO: 5 DIAS CORRIDOS 10.OBS FINAIS:
A14: 3841052 | B14: MIRIAN DE SOUZA DOS SANTOS | C14: Encerramento | D14: SERVIÇO - PF | E14: Rua | F14: RUA MARIANA MENDES | G14: 234 | H14: Guaiúba | I14: PINHEIRO | J14: -4.043295e+15 | K14: -3.863941e+15 | L14: LUCIEUDO BANDEIRA ALVES FILHO | M14: MARIA ENILANE DA SILVA SOUZA ALMEIDA | N14: 46260 | O14: 46263 | P14: 46266 | Q14: 46266 | R14: Sim | S14: 3 | T14: Cliente Pessoa Física | U14: Serviço | V14: Configuração de Repetidor | W14: Taxa Faturada | X14: Troca Conector - Desgastado | AA14: OLT Guaiúba VLAN 2109 | AB14: 🪜🧰 PENDÊNCIA 🧰🪜*Data:* 01/09/2026*Técnico:* Lucieldo Bandeira*Cliente:* MIRIAN DE SOUZA DOS SANTOS*Endereço* RUA MARIANA MENDES, 234, PINHEIRO - Guaiúba*Material utilizado*02 RJ4510 FIXA FIO 23 m de cabo utp *Obs:* RELOCAÇÃO DE EQUIPAMENTO FEITA PRA ONDE O CLIENTE PEDIU 40 reais da visita técnica conforme tem na o.s*Classificação de Encerramento:* Resolvido ✅Dispositivo: motorola moto g04Versão do Android: 14Versão do V·Tasks: 5.9.211 Status alterado de Reagendado para Encerramento | AC14: 26/08/2026 - 14:46 1.SOLICITAÇÃO: cliente solicita que seu repetidor seja realocado3.CONTATO TELEFÔNICO (01): 85987012954FONE 02(WHATSAPP) 859870129544.E-MAIL: my86917894@gmail.com5.WHATSAPP: 859870129546.PONTO DE REFERÊNCIA: Rua: Mariana Mendes N:234 CasaDepois do primeiro quebra mola7.DISPONIBILIDADE: sim 8.VALOR DO SERVIÇO / FORMA DE PAGAMENTO E VALORES: R$ 40,00 + Cabo de rede (CAT 5): R$2,00 + (metro) Conector (RJ45): R$2,00 (unidade)9.PRAZO: 5 DIAS CORRIDOS10.OBS FINAIS:
A15: 3841136 | B15: MOISES ARAUJO DE SOUSA | C15: Encerramento | D15: PENDÊNCIA FIBRA - PF | E15: Rua | F15: Rua José Baltazar de Queiroz | G15: 167 | H15: Choró | I15: Alto do cruzeiro | J15: -4.8448441e+15 | K15: -3.9134194e+15 | L15: ANTONIO TIAGO AMANCIO DA SILVA | M15: KAROL HELLEN DE ALMEIDA SILVA | N15: 46260 | O15: 46261 | P15: 46268 | Q15: 46268 | R15: Sim | S15: 7 | T15: Cliente Pessoa Física | U15: Pendência | V15: Teste de Velocidade | W15: Validação de Serviço/Velocidade | X15: Troca Conector - Desgastado | AA15: OLT Choro VLAN 4004 | AB15: ♦️ *PENDÊNCIA* ♦️*Data:* 03/09/2026*Técnico:* Tiago*Auxiliar:* Amaury *Cliente:* MOISES ARAUJO DE SOUSA*Endereço:* Rua José Baltazar de Queiroz, 167, Alto*Classificação de Encerramento:*RESOLVIDOTESTE FEITO, SEM NENHUM DEFEITO OU PROBLEMA, TUDO OPERANDO NORMAL Dispositivo: Xiaomi 23100RN82LVersão do Android: 15Versão do V·Tasks: 5.9.211 Status alterado de Agendado para Encerramento | AC15: 26/08/2026 - 15:40 01. RELATO DO CLIENTE: cliente relata que não esta conseguindo abrir alguns aplicativos por conta da lentidão e oscilação do wifi , feito as configurações mas continuou da mesma forma02. ANÁLISE SISTEMA (UNM):online03. ANÁLISE SISTEMA (VOALLE):online04. EXTRATO COM QUEDAS: NÃO05. GERENCIAMENTO REM. HABILITADO: SIM 06. PROCEDIMENTO REALIZADO:vconfigurações07. POTÊNCIA:25.23 08. CAIXA E PORTA:cx7859 p-1008. CONTATO:88 99743702409. ENDEREÇO COMPLETO:Rua José Baltazar de Queiroz 167, Alto do cruzeiro - Choró, CE10. CONDOMÍNIO: uNÃO10. PONTO DE REFERÊNCIA:Próxima da casa do sr Lauro Casa grande de varanda11. DISPONIBILIDADE:sim , dia todo12. OBSERVAÇÃO:
A16: 3841282 | B16: FRANCISCA IVANILDA INACIO RIBEIRO | C16: Encerramento | D16: INSTALAÇÃO FIBRA - COND. | E16: Rua | F16: Rua João de Castro | G16: 555 | H16: Aquiraz | I16: Loteamento Bela Vista do Sul | J16: -3916617 | K16: -38383185 | L16: HALLEF GUILHERME LIMA CLEMENTE SILVA | M16: VANESSA DA COSTA ABREU | N16: 46260 | O16: 46261 | P16: 46266 | Q16: 46266 | R16: Sim | S16: 5 | T16: Cliente Condomínio | U16: Instalação | X16: Troca Conector - Desgastado | AA16: OLT Aquiraz VLAN 12 | AB16: 🛠 *INSTALAÇÃO* 🧰*Data:* 01/09/2026 *Técnico:* Hallef / Ismael*Cliente:* FRANCISCA IVANILDA INACIO RIBEIRO*Endereço:* Rua João de Castro, 555, Loteamento Bela Vista do Sul - Aquiraz Condomínio Monte Carmelhttps://maps.app.goo.gl/jNvGd6RSEewt1Ths8 *Potência:* -22*Caixa:* 10545*porta*: 16*MATERIAL USADO* Conector verde 2und Conector azulAdesivoPetcord Fixa fio 5und Canaleta EQUIPAMENTOS * Ont : FHTTFE258C38* Roteador.* ONU *inicial:* 495*Final:* 340*Metragem:* 155m *Serviço Realizado:* Instalação Feito os testes com o cliente.*Classificação de Encerramento:* Instalação Concluída.Dispositivo: motorola moto g04sVersão do Android: 14Versão do V·Tasks: 5.9.211 Status alterado de Reagendado para Encerramento | AC16: VENDEDOR: Vanessa AbreuÁREA: PAP () CALL-CENTER ( ) LOJA (x ) TBR ( )TITULAR: FRANCISCA IVANILDA INACIO RIBEIROTELEFONE: 85988972277WHATSAPP: 85988972277DISPONIBILIDADE: MANHA( ) TARDE ( ) DIA TODO (X)DATA: 27/08/2026CIDADE E BAIRRO: R. João de Castro, 555 (1° Andar- Apt 101) - Lot. Bela Vista do Sul, Aquiraz (Cond. Monte Carmel).PLANO: 500mbVALOR ORIGINAL DO PLANO: 99,99POSSUI DESCONTO DE PONTUALIDADE? SIM ( ) NÃO (x )SE SIM: D5 ( ) ou DNET - D10( )DESCONTO DE __ , SE PAGO ATÉ O VENCIMENTO POR 12 MESESTAXA INSTALAÇÃO: GrátisATENDIMENTO REGISTRADO:Google Drive ( ) Fortics ( ) Smart ( ) Voalle (x)FIDELIDADE: ( x) SIM NÃO ( )CLIENTE DESEJA NOTA FISCAL: SIM ( ) NÃO (x )COORD: -3.916639, -38.383238 CAIXA: 8221/82-8222-47177CASA DUPLEX ( ) CASA TERREA () Condomínio (x)QUANTOS E QUAIS APARELHOS CONECTADOS: 1 tv e 2 cellOBSERVAÇÃO ADICIONAL: Entrar em contato antes de ir.Ativação do contrato: 174015---- Endereço de Instalação ----CEP: 61700-000Logradouro: Rua João de CastroNúmero: 555Bairro: Loteamento Bela Vista do SulEstado: CECidade: AquirazComplemento: Condomínio 1° Andar Apt 101Referência: Fica no Cond Monte Carmel, Próximo a Escola Maria Margarida Ramos---- Serviços a serem ativados ----- 0422 - ULTRAINFO - 500MB
A17: 3841470 | B17: EDINEIDE DE SOUZA ABREU | C17: Encerramento | D17: SERVIÇO - COND. | E17: Rua | F17: Rua Otoni Sá | G17: 288 | H17: Eusébio | I17: Mangabeira | J17: -3.8408088e+15 | K17: -3.8427609e+16 | L17: PAULO ROBERTO ARAUJO GALVAO | M17: SUZETTE CARNEIRO LIMA DE SOUZA | N17: 46260 | O17: 46263 | P17: 46266 | Q17: 46266 | R17: Sim | S17: 3 | T17: Cliente Condomínio | U17: Serviço | V17: Configuração de Repetidor | W17: Taxa Isenta | X17: Troca Conector - Desgastado | AA17: OLT Eusébio 2 VLAN 58 | AB17: 🚧⚠️ *SERVIÇO* ⚠️🚧*Chegada**Saída**Data* 01.09.2026*SUPORTE**COMERCIAL* *Técnico* Paulo Roberto / Felipe Soares *Cliente* EDINEIDE DE SOUZA ABREU*Endereço* Rua Otoni Sá, 288, Mangabeira - Eusébio*obs sobre o endereço* Mangabeira*CONTATO* *Caixa* *PORTA* *SINAL DO CAIXA**SINAL DO CLIENTE**Velocidade* *Material utilizado*0 Conector Verde 0 Conector Azul0 Fixa fios 0 canaleta0 Esticado0 adesivo 0 Per Cord0 RJ45PROBLEMA RELATADO: Foi solicitado visita técnica para manutenção no repetidor de sinal da sala, roteador foi reconfigurado, alterada algumas configurações e a conexão foi restabelecida.Após procedimentos foram realizados testes junto a cliente e navegou normalmente em todos os dispositivos.OBS. *TAXA:* *Isenta*Cabo de redeInicial 000Final 000Metragem 000*SENHA DO EQUIPAMENTO**Equipamento anterior**MAC* *Equipamento Atual* *MAC* *Drop inicial* *Drop Final* *Metragem**Classificação de Encerramento*RESOLVIDO✅Dispositivo: motorola moto g04sVersão do Android: 14Versão do V·Tasks: 5.9.203 Status alterado de Reagendado para Encerramento | AC17: 26/08/2026 - 17:16 1.SOLICITAÇÃO: cliente informa que o seu repetidor não está aparecendo a rede3.CONTATO TELEFÔNICO (01): 85987404993 (85)98526-1251FONE 02(WHATSAPP) 85987404993 (85)99408-41314.E-MAIL: claudianaalvesroqueroque@gmail.com5.WHATSAPP: 859874049936.PONTO DE REFERÊNCIA: prox ao seu esfirra7.DISPONIBILIDADE: total8.VALOR DO SERVIÇO / FORMA DE PAGAMENTO E VALORES: Verificar no Guia Ultra e insira aqui as informações. Taxa Isenta9.PRAZO: 5 DIAS CORRIDOS 10.OBS FINAIS:
A18: 3842107 | B18: KARINA CARVALHO DOS SANTOS | C18: Encerramento | D18: PENDÊNCIA FIBRA - PF | E18: Rua | F18: RUA ARABAIANA | G18: 69 | H18: Fortaleza | I18: Barra do Ceará | L18: FRANCISCO JHONATA DA COSTA | M18: MARIANA ABREU DA SILVA | N18: 46261 | O18: 46262 | P18: 46266 | Q18: 46266 | R18: Sim | S18: 4 | T18: Cliente Pessoa Física | U18: Pendência | V18: LOS | W18: Fibra Sem Sinal / Luz Los Vermelha | X18: Troca Conector - Desgastado | AA18: OLT Barra do Ceará VLAN 1001 | AB18: *PENDENCIA**Data* 01/09/2026*Técnico* Jhonata CLIENTE:KARINA CARVALHO DOS SANTOSENDERECO:RUA ARABAIANA, 69, Barra do Ceará - Fortaleza*Caixa* :Giga*Porta*:*SINAL DA CAIXA*.-17*SINAL DO CLIENTE*-17SERVIÇO REALIZADO Feito Troca dos dois conectores Apc na Cto e Upc na Onu...01Conector Verde01Conector Azul00Fixa fio00 Canaleta00 Esticador01Adesivo conector00 RJ4500 pat Cord00 ONU XPON AX 180000 Roteador Mercusis *OBS* : Normalizada, Internet ok.. Login:multiproSenha:multipro*VALOR* :*Cabo inicial*:*Cabo final* *Metragem* *Drop inicial*:0000*Drop final* : 0000*Metragem*0000Dispositivo: samsung SM-A075MVersão do Android: 16Versão do V·Tasks: 5.9.206 Status alterado de Remarcação para Encerramento | AC18: 27/08/2026 - 10:14 01. RELATO DO CLIENTE: SEM INTERNET,NAO TEM LED PISCANDO VERMELHO02. ANÁLISE SISTEMA (UNM):OFF03. ANÁLISE SISTEMA (VOALLE):OFF04. EXTRATO COM QUEDAS: SIM ou NÃO05. GERENCIAMENTO REM. HABILITADO: SIM ou NÃO06. PROCEDIMENTO REALIZADO:TIROU DA TOMADA07. POTÊNCIA:X08. CAIXA E PORTA:2612/0808. CONTATO:(85)99216-134309. ENDEREÇO COMPLETO:RUA ARABAIANA, 69 - Barra do Ceará - Fortaleza - CE - CEP 60332-41010. CONDOMÍNIO: SIM (Nome) ou NÃO10. PONTO DE REFERÊNCIA:Próximo a rua da feira11. DISPONIBILIDADE:O DIA TODO, POREM PEDE URGENCIA POIS TRABALHA EM HOMEOFFICE12. OBSERVAÇÃO:
A19: 3842160 | B19: CAMILLUS DE LELLIS FREITAS DE SOUSA | C19: Encerramento | D19: PENDÊNCIA FIBRA - PF | E19: Rua | F19: Rua José Nogueira | G19: 183 | H19: Fortaleza | I19: Pedras | J19: -38888642 | K19: -385100559 | L19: MARCOS AURELIO DE SOUSA OLIVEIRA | M19: SUZANA SANTOS MOURA | N19: 46261 | O19: 46262 | P19: 46266 | Q19: 46266 | R19: Sim | S19: 4 | T19: Cliente Pessoa Física | U19: Pendência | V19: LOS | W19: Fibra Sem Sinal / Luz Los Vermelha | X19: Troca Conector - Desgastado | AA19: OLT Jabuti VLAN 1000 | AB19: *Manutenção* *Data* 01. 09.2026*Técnico*: Marcos Aurélio*CLIENTE* CAMILLUS DE LELLIS FREITAS DE SOUSA *ENDEREÇO* Rua José Nogueira, 183, Pedras - Fortaleza*Caixa*: 11930*Porta*: 12*SINAL DA CAIXA*: 24*SINAL DO CLIENTE*: 24*SERVIÇO REALIZADO:* Manutenção *Material utilizado*02 Conector Verde00 Conector Azul00 Fixa fio00 Canaleta00 Esticador00 Adesivo conector 00 RJ4500 patch cord*Equipamento utilizado**Equipamentos retirados* *Obs*: drop atenuado, desfeito atenuação.*VALOR*:*Cabo inicial* *Cabo final* *Metragem*Dispositivo: samsung SM-A075MVersão do Android: 16Versão do V·Tasks: 5.9.211 Status alterado de Agendado para Encerramento | AC19: 27/08/2026 - 10:43 01. RELATO DO CLIENTE: Cliente sem conexão, luz vermelha piscando no equipamento, alarme link loss no unm02. ANÁLISE SISTEMA (UNM): link loss03. ANÁLISE SISTEMA (VOALLE): off04. EXTRATO COM QUEDAS: xx05. GERENCIAMENTO REM. HABILITADO: xx06. PROCEDIMENTO REALIZADO: reboot07. POTÊNCIA: xx08. CAIXA E PORTA: 11930/0208. CONTATO: (85)98510-0521- (85)99701-704709. ENDEREÇO COMPLETO:Rua José Nogueira, 183 - Pedras (3° casa)10. CONDOMÍNIO: NÃO10. PONTO DE REFERÊNCIA:Próximo ao posto de saúde / Está tendo obra da prefeitura bem em frente. Então tem um pedaço da rua interditada 11. DISPONIBILIDADE: total12. OBSERVAÇÃO:Está tendo obra da prefeitura bem em frente. Então tem um pedaço da rua interditada
A20: 3842180 | B20: FRANCISCA FLAVIA GOMES DE SOUSA PONTO 02 | C20: Encerramento | D20: DNET - REPETIDOR - PF | E20: Rua | F20: Rua Lagoa do Mato | G20: S/N | H20: Aquiraz | I20: Justiniano de Serpa | J20: -4032329 | K20: -385067652 | L20: CAIO VICTOR MONTEIRO DE OLIVEIRA | M20: RUAN VICTOR SANTOS SOUZA CLARINDO | N20: 46261 | O20: 46264 | P20: 46267 | Q20: 46267 | R20: Sim | S20: 3 | T20: DNET - Cliente Pessoa Física | U20: DNET - Repetidor | V20: DNET - Inclusão Ultra Repetidor 4.0 | W20: DNET - Faturar Material Excedente | X20: Troca Conector - Desgastado | AA20: OLT DNET TEMPORARIO | AB20: Abertura Solicitação para visita técnica no cliente, a pedido do mesmo.TÉCNICO : CAIO VICTOR CLIENTE : FRANCISCA FLAVIA GOMES DE SOUSA PONTO 02ENDEREÇO CORRETO: Rua Lagoa do Mato, S/N, Justiniano de Serpa - AquirazNº CAIXA: N º PORTA: VERIFICAÇÃO DE CX: SINAL DA CTO: SINAL DO CLIENTE: MATERIAL UTILIZADO*CONECTOR VERDE: CONECTOR AZUL: FIXA FIO: CANALETA: ESTICADOR: ADESIVO CONECTOR: RJ45: 2CABO DE REDE: 20mtEQUIPAMENTO UTILIZADO ONT (S/N) = ONU (S/N) = ROTEADOR (S/N) = DROP CABO INICIAL: DROP CABO FINAL: DROP METRAGEM: TEVE FATURAMENTO? VALOR (SE HOUVER) :SERVIÇO:Dispositivo: motorola moto g04sVersão do Android: 14Versão do V·Tasks: 5.9.211 Status alterado de Andamento para Encerramento | AC20: 27/08/2026 - 11:04 1.SOLICITAÇÃO: Inclusão Ultra Repetidor 4.02.ROTEADOR É DO CLIENTE ( ) ,COMODATO (x) OU LOCAÇÃO ( )? 3.CONTATO TELEFÔNICO (01): 85996819710. 859968527383. (WHATSAPP): 859968197104.WHATSAPP: 859968527385.PONTO DE REFERÊNCIA: Bar do lindo6.DISPONIBILIDADE: Total7.VALOR DO SERVIÇO / FORMA DE PAGAMENTO E VALORES: Mensalidade do aluguel: R$22,99Cabo de rede (até 30 metros) e conectores incluso.8.PRAZO: 5 DIAS CORRIDOS A PARTIR DA ABERTURA DO ATENDIMENTO DO NÍVEL 09.OBS FINAIS:
A21: 3842265 | B21: SYLMARA SILVA ARAUJO | C21: Encerramento | D21: DNET - PENDENCIA FIBRA - PF | E21: Rua | F21: RUA MANUEL COSTA | G21: 704 | H21: Fortaleza | I21: PAUPINA | J21: -38603951 | K21: -384912356 | L21: EVERLAN DA PENHA TOME | M21: MARCOS VINICIUS ALVES DE OLIVEIRA | N21: 46261 | O21: 46262 | P21: 46266 | Q21: 46266 | R21: Sim | S21: 4 | T21: DNET - Cliente Pessoa Física | U21: DNET - Pendência | V21: DNET - LOS | W21: DNET - Fibra Sem Sinal / Luz Los Vermelha | X21: Troca Conector - Desgastado | AA21: OLT DNET TEMPORARIO | AB21: ATIVIDADE MANUTENÇÃO ⚡Data:01/09/2026TÉCNICO: Everlan Tomé AUXILIARES:Cliente:SYLMARA SILVA ARAUJOENDEREÇO:RUA MANUEL COSTA, 704, PAUPINA - FortalezaACESSO REMOTO : Sim ( x ) Não ( )SERVIÇO: Reparo PRODUTOS:02 conector verde Obs feito troca dos conectores ont e caixaPATRIMONIO RECOLHIMENTO:DROP INICIAL DROP FINAL CAIXA : 11457PORTA: 16ACESSO REMOTO : Sim ( x ) Não ( )SERVIÇO: ReparoRECOLHIMENTOCLASSIFICAÇÃO DE ENCERRAMENTO : Finalizado✅Dispositivo: motorola moto g(9) playVersão do Android: 11Versão do V·Tasks: 5.9.211 Status alterado de Reagendado para Encerramento | AC21: 27/08/2026 - 11:25 01. RELATO DO CLIENTE: cliente relata que possui luzes verdes,sem internet e reinicia mais não conecta02. ANÁLISE SISTEMA (UNM): ofline03. ANÁLISE SISTEMA (VOALLE):ofline04. EXTRATO COM QUEDAS: NÃO05. GERENCIAMENTO REM. HABILITADO: verificar06. PROCEDIMENTO REALIZADO:reboot no equipamento07. POTÊNCIA:xxxxxxxxxxxxxxxxxxx08. CAIXA E PORTA:CX11457 P-0308. CONTATO:88 99735-1400 ou 88 99955-342009. ENDEREÇO COMPLETO:RUA MANUEL COSTA 704, PAUPINA - Fortaleza, CE60873-54010. CONDOMÍNIO: NÃO10. PONTO DE REFERÊNCIA:: Na mesma rua que a oficina HP Disel11. DISPONIBILIDADE:dia todo12. OBSERVAÇÃO:
